f() -/>
  try: await g() catch err: err
